I'm sorry, but an uncaught exception occurred.

While loading the script.
ScriptError: Name ('game/characters.rpy', 1735388839, 1) is defined twice, at game/characters.rpy:1 and game/game/characters.rpyc:1.

-- Full Traceback ------------------------------------------------------------

Full traceback:
  File "C:\Users\User\Desktop\renpy-8.3.4-sdk\renpy\bootstrap.py", line 359, in bootstrap
    renpy.main.main()
  File "C:\Users\User\Desktop\renpy-8.3.4-sdk\renpy\main.py", line 470, in main
    renpy.game.script.load_script() # sets renpy.game.script.
  File "C:\Users\User\Desktop\renpy-8.3.4-sdk\renpy\script.py", line 359, in load_script
    self.load_appropriate_file(".rpyc", [ "_ren.py", ".rpy" ], dir, fn, initcode)
  File "C:\Users\User\Desktop\renpy-8.3.4-sdk\renpy\script.py", line 957, in load_appropriate_file
    self.finish_load(stmts, initcode, filename=lastfn) # type: ignore
  File "C:\Users\User\Desktop\renpy-8.3.4-sdk\renpy\script.py", line 590, in finish_load
    check_name(node)
  File "C:\Users\User\Desktop\renpy-8.3.4-sdk\renpy\script.py", line 566, in check_name
    raise ScriptError("Name %s is defined twice, at %s:%d and %s:%d." %
ScriptError: Name ('game/characters.rpy', 1735388839, 1) is defined twice, at game/characters.rpy:1 and game/game/characters.rpyc:1.

Windows-10-10.0.19045 AMD64
Ren'Py 8.3.4.24120703
 
Sun Jan 19 11:29:25 2025
