I'm sorry, but an uncaught exception occurred.

While running game code:
  File "game/day_2.rpy", line 19, in script
    show ziad show ziad with dissolve
Exception: Image 'ziad' does not accept attributes 'show ziad'.

-- Full Traceback ------------------------------------------------------------

Full traceback:
  File "game/day_2.rpy", line 19, in script
    show ziad show ziad with dissolve
  File "C:\Users\User\Desktop\renpy-8.3.4-sdk\renpy\ast.py", line 1117, in execute
    show_imspec(self.imspec, atl=getattr(self, "atl", None))
  File "C:\Users\User\Desktop\renpy-8.3.4-sdk\renpy\ast.py", line 1080, in show_imspec
    renpy.config.show(name,
  File "C:\Users\User\Desktop\renpy-8.3.4-sdk\renpy\exports\displayexports.py", line 477, in show
    if not base.find_target() and renpy.config.missing_show:
  File "C:\Users\User\Desktop\renpy-8.3.4-sdk\renpy\display\image.py", line 421, in find_target
    self.target = target._duplicate(a)
  File "C:\Users\User\Desktop\renpy-8.3.4-sdk\renpy\display\displayable.py", line 249, in _duplicate
    args.extraneous()
  File "C:\Users\User\Desktop\renpy-8.3.4-sdk\renpy\display\displayable.py", line 109, in extraneous
    raise Exception("Image '{}' does not accept attributes '{}'.".format(
Exception: Image 'ziad' does not accept attributes 'show ziad'.

Windows-10-10.0.19045 AMD64
Ren'Py 8.3.4.24120703
The Letter 
Tue Dec 31 08:32:27 2024
